Workbook

Sheet Cover
B1: FPT CORPORATION - INTEGRATED FINANCIAL MODEL
B2: Cleaned & consolidated build - navigation index
B3: Last structural update: 2026-07-20 | 15 sheets (12 visible)
B5: BASIS CHANGE (FY2026): | C5: FPT Telecom now equity-method (deconsolidated); 2025 restated. 1Q26/2Q26/6M26 = NEW basis, history = OLD basis - see YoY sheet.
B6: MERGES: | C6: Data feeds -> Data. FI&FE folded into PL (rows 371+). Capex_WC folded into BS (rows 211+).
B8: GROUP | C8: SHEET | D8: DESCRIPTION
B9: Control | C9: Scenarios | D9: Scenario switch + macro assumptions
B10: Analysis | C10: YoY | D10: YoY dashboard - annual + quarterly + 2026 new-basis
B11: Model | C11: Revenue | D11: Revenue & PBT build by segment
B12: Output | C12: Valuation | D12: DCF / FCFF valuation
B13: Model | C13: PL | D13: Income statement (now incl. FI&FE schedule, rows 371+)
B14: Model | C14: BS | D14: Balance sheet (now incl. Capex/WC schedule, rows 211+)
B15: Model | C15: CF | D15: Cash flow / FCFF
B16: Control | C16: Assumptions | D16: Forecast drivers: growth rates, margins
B17: Data | C17: Data | D17: Merged FiinPro actuals (Fi_BS+Fi_PL+Fi_CF+Data_Quarterly, extract 03/2023 - STALE)
B18: Output | C18: Report | D18: Formatted statements for publication
B19: Output | C19: Ratios | D19: Financial ratios
... B22: Data | C22: Beta (hidden) | D22: Beta regression vs VN-Index

Sheet YoY
B1: FPT — YoY COMPARISON DASHBOARD
B2: A & B = consolidated (old) basis incl. Telecom. C = 2026 actuals on NEW (post-deconsolidation) basis; YoY vs restated 2025 — not comparable to A/B.
B3: Live formulas link to the Revenue sheet. Growth auto-coloured: green = up, red = down.
B5: A. ANNUAL (VND bn; % = YoY)
B6: Metric | C6: 2018 | D6: 2019 | E6: 2020 | F6: 2021 | G6: 2022 | H6: 2023 | I6: 2024 | J6: 2025 | K6: 2026F | L6: 2027F | M6: 2028F
B7: Total net revenue | C7: =IF(Revenue!B10=0,"",Revenue!B10) -> 23213.537 | D7: =IF(Revenue!C10=0,"",Revenue!C10) -> 27716.96 | E7: =IF(Revenue!D10=0,"",Revenue!D10) -> 29830.401 | F7: =IF(Revenue!E10=0,"",Revenue!E10) -> 35657.263 | G7: =IF(Revenue!F10=0,"",Revenue!F10) -> 44009.528 | H7: =IF(Revenue!G10=0,"",Revenue!G10) -> 52618 | I7: =IF(Revenue!H10=0,"",Revenue!H10) -> 62850 | J7: =IF(Revenue!I10=0,"",Revenue!I10) -> 70114 | ... M7: =IF(Revenue!L10=0,"",Revenue!L10) -> 103820.32
B8: % YoY | D8: =IF(OR(Revenue!C10=0,Revenue!B10=0),"",Revenue!C10/Revenue!B10-1) -> 0.19399988 | E8: =IF(OR(Revenue!D10=0,Revenue!C10=0),"",Revenue!D10/Revenue!C10-1) -> 0.0762508 | F8: =IF(OR(Revenue!E10=0,Revenue!D10=0),"",Revenue!E10/Revenue!D10-1) -> 0.19533301 | G8: =IF(OR(Revenue!F10=0,Revenue!E10=0),"",Revenue!F10/Revenue!E10-1) -> 0.23423742 | H8: =IF(OR(Revenue!G10=0,Revenue!F10=0),"",Revenue!G10/Revenue!F10-1) -> 0.19560474 | I8: =IF(OR(Revenue!H10=0,Revenue!G10=0),"",Revenue!H10/Revenue!G10-1) -> 0.19445817 | J8: =IF(OR(Revenue!I10=0,Revenue!H10=0),"",Revenue!I10/Revenue!H10-1) -> 0.11557677 | K8: =IF(OR(Revenue!J10=0,Revenue!I10=0),"",Revenue!J10/Revenue!I10-1) -> 0.12595076 | ... M8: =IF(OR(Revenue!L10=0,Revenue!K10=0),"",Revenue!L10/Revenue!K10-1) -> 0.14965845
B9: Technology (Total IT services) | C9: =IF(Revenue!B11=0,"",Revenue!B11) -> 13401.574 | D9: =IF(Revenue!C11=0,"",Revenue!C11) -> 15783.421 | E9: =IF(Revenue!D11=0,"",Revenue!D11) -> 16804.932 | F9: =IF(Revenue!E11=0,"",Revenue!E11) -> 20872.244 | G9: =IF(Revenue!F11=0,"",Revenue!F11) -> 25762.902 | H9: =IF(Revenue!G11=0,"",Revenue!G11) -> 31449 | I9: =IF(Revenue!H11=0,"",Revenue!H11) -> 39110 | J9: =IF(Revenue!I11=0,"",Revenue!I11) -> 44475 | ... M9: =IF(Revenue!L11=0,"",Revenue!L11) -> 68460.16
B10: % YoY | D10: =IF(OR(Revenue!C11=0,Revenue!B11=0),"",Revenue!C11/Revenue!B11-1) -> 0.1777289 | E10: =IF(OR(Revenue!D11=0,Revenue!C11=0),"",Revenue!D11/Revenue!C11-1) -> 0.064720506 | F10: =IF(OR(Revenue!E11=0,Revenue!D11=0),"",Revenue!E11/Revenue!D11-1) -> 0.24203085 | G10: =IF(OR(Revenue!F11=0,Revenue!E11=0),"",Revenue!F11/Revenue!E11-1) -> 0.23431395 | H10: =IF(OR(Revenue!G11=0,Revenue!F11=0),"",Revenue!G11/Revenue!F11-1) -> 0.22070875 | I10: =IF(OR(Revenue!H11=0,Revenue!G11=0),"",Revenue!H11/Revenue!G11-1) -> 0.24360075 | J10: =IF(OR(Revenue!I11=0,Revenue!H11=0),"",Revenue!I11/Revenue!H11-1) -> 0.13717719 | K10: =IF(OR(Revenue!J11=0,Revenue!I11=0),"",Revenue!J11/Revenue!I11-1) -> 0.14122556 | ... M10: =IF(OR(Revenue!L11=0,Revenue!K11=0),"",Revenue!L11/Revenue!K11-1) -> 0.16560096
B11: Global IT (foreign) | C11: =IF(Revenue!B12=0,"",Revenue!B12) -> 8443.472 | D11: =IF(Revenue!C12=0,"",Revenue!C12) -> 10848.063 | E11: =IF(Revenue!D12=0,"",Revenue!D12) -> 12000.26 | F11: =IF(Revenue!E12=0,"",Revenue!E12) -> 14540.801 | G11: =IF(Revenue!F12=0,"",Revenue!F12) -> 18915.494 | H11: =IF(Revenue!G12=0,"",Revenue!G12) -> 24288 | I11: =IF(Revenue!H12=0,"",Revenue!H12) -> 30953 | J11: =IF(Revenue!I12=0,"",Revenue!I12) -> 35382 | ... M11: =IF(Revenue!L12=0,"",Revenue!L12) -> 55685.15
B12: % YoY | D12: =IF(OR(Revenue!C12=0,Revenue!B12=0),"",Revenue!C12/Revenue!B12-1) -> 0.28478699 | E12: =IF(OR(Revenue!D12=0,Revenue!C12=0),"",Revenue!D12/Revenue!C12-1) -> 0.10621223 | F12: =IF(OR(Revenue!E12=0,Revenue!D12=0),"",Revenue!E12/Revenue!D12-1) -> 0.21170716 | G12: =IF(OR(Revenue!F12=0,Revenue!E12=0),"",Revenue!F12/Revenue!E12-1) -> 0.3008564 | H12: =IF(OR(Revenue!G12=0,Revenue!F12=0),"",Revenue!G12/Revenue!F12-1) -> 0.28402673 | I12: =IF(OR(Revenue!H12=0,Revenue!G12=0),"",Revenue!H12/Revenue!G12-1) -> 0.27441535 | J12: =IF(OR(Revenue!I12=0,Revenue!H12=0),"",Revenue!I12/Revenue!H12-1) -> 0.14308791 | K12: =IF(OR(Revenue!J12=0,Revenue!I12=0),"",Revenue!J12/Revenue!I12-1) -> 0.14668042 | ... M12: =IF(OR(Revenue!L12=0,Revenue!K12=0),"",Revenue!L12/Revenue!K12-1) -> 0.17659111
B13: Domestic IT | C13: =IF(Revenue!B13=0,"",Revenue!B13) -> 4958.102 | D13: =IF(Revenue!C13=0,"",Revenue!C13) -> 4935.358 | E13: =IF(Revenue!D13=0,"",Revenue!D13) -> 4804.672 | F13: =IF(Revenue!E13=0,"",Revenue!E13) -> 6331.443 | G13: =IF(Revenue!F13=0,"",Revenue!F13) -> 6847.408 | H13: =IF(Revenue!G13=0,"",Revenue!G13) -> 7161 | I13: =IF(Revenue!H13=0,"",Revenue!H13) -> 8157 | J13: =IF(Revenue!I13=0,"",Revenue!I13) -> 9093 | ... M13: =IF(Revenue!L13=0,"",Revenue!L13) -> 12775.01
B14: % YoY | D14: =IF(OR(Revenue!C13=0,Revenue!B13=0),"",Revenue!C13/Revenue!B13-1) -> -0.0045872392 | E14: =IF(OR(Revenue!D13=0,Revenue!C13=0),"",Revenue!D13/Revenue!C13-1) -> -0.026479538 | F14: =IF(OR(Revenue!E13=0,Revenue!D13=0),"",Revenue!E13/Revenue!D13-1) -> 0.317768 | G14: =IF(OR(Revenue!F13=0,Revenue!E13=0),"",Revenue!F13/Revenue!E13-1) -> 0.081492481 | H14: =IF(OR(Revenue!G13=0,Revenue!F13=0),"",Revenue!G13/Revenue!F13-1) -> 0.045797183 | I14: =IF(OR(Revenue!H13=0,Revenue!G13=0),"",Revenue!H13/Revenue!G13-1) -> 0.13908672 | J14: =IF(OR(Revenue!I13=0,Revenue!H13=0),"",Revenue!I13/Revenue!H13-1) -> 0.11474807 | K14: =IF(OR(Revenue!J13=0,Revenue!I13=0),"",Revenue!J13/Revenue!I13-1) -> 0.12 | ... M14: =IF(OR(Revenue!L13=0,Revenue!K13=0),"",Revenue!L13/Revenue!K13-1) -> 0.12
B15: Telecom | C15: =IF(Revenue!B14=0,"",Revenue!B14) -> 8831.003 | D15: =IF(Revenue!C14=0,"",Revenue!C14) -> 10398.427 | E15: =IF(Revenue!D14=0,"",Revenue!D14) -> 11466.154 | F15: =IF(Revenue!E14=0,"",Revenue!E14) -> 12686.416 | G15: =IF(Revenue!F14=0,"",Revenue!F14) -> 14729.649 | H15: =IF(Revenue!G14=0,"",Revenue!G14) -> 15806 | I15: =IF(Revenue!H14=0,"",Revenue!H14) -> 17610 | J15: =IF(Revenue!I14=0,"",Revenue!I14) -> 19507 | ... M15: =IF(Revenue!L14=0,"",Revenue!L14) -> 27283.583
B16: % YoY | D16: =IF(OR(Revenue!C14=0,Revenue!B14=0),"",Revenue!C14/Revenue!B14-1) -> 0.17749105 | E16: =IF(OR(Revenue!D14=0,Revenue!C14=0),"",Revenue!D14/Revenue!C14-1) -> 0.10268159 | F16: =IF(OR(Revenue!E14=0,Revenue!D14=0),"",Revenue!E14/Revenue!D14-1) -> 0.10642296 | G16: =IF(OR(Revenue!F14=0,Revenue!E14=0),"",Revenue!F14/Revenue!E14-1) -> 0.16105676 | H16: =IF(OR(Revenue!G14=0,Revenue!F14=0),"",Revenue!G14/Revenue!F14-1) -> 0.073073771 | I16: =IF(OR(Revenue!H14=0,Revenue!G14=0),"",Revenue!H14/Revenue!G14-1) -> 0.11413387 | J16: =IF(OR(Revenue!I14=0,Revenue!H14=0),"",Revenue!I14/Revenue!H14-1) -> 0.10772288 | K16: =IF(OR(Revenue!J14=0,Revenue!I14=0),"",Revenue!J14/Revenue!I14-1) -> 0.115 | ... M16: =IF(OR(Revenue!L14=0,Revenue!K14=0),"",Revenue!L14/Revenue!K14-1) -> 0.12
B17: Education, Investment & others | C17: =IF(Revenue!B17=0,"",Revenue!B17) -> 980.95986 | D17: =IF(Revenue!C17=0,"",Revenue!C17) -> 1535.1122 | E17: =IF(Revenue!D17=0,"",Revenue!D17) -> 1559.3145 | F17: =IF(Revenue!E17=0,"",Revenue!E17) -> 2098.6025 | G17: =IF(Revenue!F17=0,"",Revenue!F17) -> 3516.9767 | H17: =IF(Revenue!G17=0,"",Revenue!G17) -> 5363 | I17: =IF(Revenue!H17=0,"",Revenue!H17) -> 6129 | J17: =IF(Revenue!I17=0,"",Revenue!I17) -> 6132 | ... M17: =IF(Revenue!L17=0,"",Revenue!L17) -> 8076.5798
B18: % YoY | D18: =IF(OR(Revenue!C17=0,Revenue!B17=0),"",Revenue!C17/Revenue!B17-1) -> 0.56490823 | E18: =IF(OR(Revenue!D17=0,Revenue!C17=0),"",Revenue!D17/Revenue!C17-1) -> 0.015765867 | F18: =IF(OR(Revenue!E17=0,Revenue!D17=0),"",Revenue!E17/Revenue!D17-1) -> 0.34584942 | G18: =IF(OR(Revenue!F17=0,Revenue!E17=0),"",Revenue!F17/Revenue!E17-1) -> 0.67586601 | H18: =IF(OR(Revenue!G17=0,Revenue!F17=0),"",Revenue!G17/Revenue!F17-1) -> 0.52488927 | I18: =IF(OR(Revenue!H17=0,Revenue!G17=0),"",Revenue!H17/Revenue!G17-1) -> 0.14283051 | J18: =IF(OR(Revenue!I17=0,Revenue!H17=0),"",Revenue!I17/Revenue!H17-1) -> 0.00048947626 | K18: =IF(OR(Revenue!J17=0,Revenue!I17=0),"",Revenue!J17/Revenue!I17-1) -> 0.05 | ... M18: =IF(OR(Revenue!L17=0,Revenue!K17=0),"",Revenue!L17/Revenue!K17-1) -> 0.12
B19: Gross profit | C19: =IF(Revenue!B7=0,"",Revenue!B7) -> 8722.879 | D19: =IF(Revenue!C7=0,"",Revenue!C7) -> 10712.05 | E19: =IF(Revenue!D7=0,"",Revenue!D7) -> 11813.657 | F19: =IF(Revenue!E7=0,"",Revenue!E7) -> 13631.964 | G19: =IF(Revenue!F7=0,"",Revenue!F7) -> 17167.279 | H19: =IF(Revenue!G7=0,"",Revenue!G7) -> 20319.553 | I19: =IF(Revenue!H7=0,"",Revenue!H7) -> 23698.34 | J19: =IF(Revenue!I7=0,"",Revenue!I7) -> 25990.27 | ... M19: =IF(Revenue!L7=0,"",Revenue!L7) -> 25577.75
B20: % YoY | D20: =IF(OR(Revenue!C7=0,Revenue!B7=0),"",Revenue!C7/Revenue!B7-1) -> 0.22804061 | E20: =IF(OR(Revenue!D7=0,Revenue!C7=0),"",Revenue!D7/Revenue!C7-1) -> 0.1028382 | F20: =IF(OR(Revenue!E7=0,Revenue!D7=0),"",Revenue!E7/Revenue!D7-1) -> 0.15391565 | G20: =IF(OR(Revenue!F7=0,Revenue!E7=0),"",Revenue!F7/Revenue!E7-1) -> 0.25934006 | H20: =IF(OR(Revenue!G7=0,Revenue!F7=0),"",Revenue!G7/Revenue!F7-1) -> 0.18362111 | I20: =IF(OR(Revenue!H7=0,Revenue!G7=0),"",Revenue!H7/Revenue!G7-1) -> 0.16628252 | J20: =IF(OR(Revenue!I7=0,Revenue!H7=0),"",Revenue!I7/Revenue!H7-1) -> 0.096712681 | K20: =IF(OR(Revenue!J7=0,Revenue!I7=0),"",Revenue!J7/Revenue!I7-1) -> -0.23726361 | ... M20: =IF(OR(Revenue!L7=0,Revenue!K7=0),"",Revenue!L7/Revenue!K7-1) -> 0.1481887
B21: Profit before tax (PBT) | C21: =IF(Revenue!B115=0,"",Revenue!B115) -> 3857.6026 | D21: =IF(Revenue!C115=0,"",Revenue!C115) -> 4664.5305 | E21: =IF(Revenue!D115=0,"",Revenue!D115) -> 5263.4566 | F21: =IF(Revenue!E115=0,"",Revenue!E115) -> 6337.2064 | G21: =IF(Revenue!F115=0,"",Revenue!F115) -> 7662.283 | H21: =IF(Revenue!G115=0,"",Revenue!G115) -> 9203.0061 | I21: =IF(Revenue!H115=0,"",Revenue!H115) -> 11069.66 | J21: =IF(Revenue!I115=0,"",Revenue!I115) -> 13133.72 | ... M21: =IF(Revenue!L115=0,"",Revenue!L115) -> 17014.728
B22: % YoY | D22: =IF(OR(Revenue!C115=0,Revenue!B115=0),"",Revenue!C115/Revenue!B115-1) -> 0.20917861 | E22: =IF(OR(Revenue!D115=0,Revenue!C115=0),"",Revenue!D115/Revenue!C115-1) -> 0.12840009 | F22: =IF(OR(Revenue!E115=0,Revenue!D115=0),"",Revenue!E115/Revenue!D115-1) -> 0.20400089 | G22: =IF(OR(Revenue!F115=0,Revenue!E115=0),"",Revenue!F115/Revenue!E115-1) -> 0.20909474 | H22: =IF(OR(Revenue!G115=0,Revenue!F115=0),"",Revenue!G115/Revenue!F115-1) -> 0.20107886 | I22: =IF(OR(Revenue!H115=0,Revenue!G115=0),"",Revenue!H115/Revenue!G115-1) -> 0.20283089 | J22: =IF(OR(Revenue!I115=0,Revenue!H115=0),"",Revenue!I115/Revenue!H115-1) -> 0.18646101 | K22: =IF(OR(Revenue!J115=0,Revenue!I115=0),"",Revenue!J115/Revenue!I115-1) | ... M22: =IF(OR(Revenue!L115=0,Revenue!K115=0),"",Revenue!L115/Revenue!K115-1) -> 0.13307511
B23: Gross margin (level) | C23: =IF(Revenue!B10=0,"",Revenue!B7/Revenue!B10) -> 0.37576691 | D23: =IF(Revenue!C10=0,"",Revenue!C7/Revenue!C10) -> 0.38647996 | E23: =IF(Revenue!D10=0,"",Revenue!D7/Revenue!D10) -> 0.39602745 | F23: =IF(Revenue!E10=0,"",Revenue!E7/Revenue!E10) -> 0.38230541 | G23: =IF(Revenue!F10=0,"",Revenue!F7/Revenue!F10) -> 0.39008096 | H23: =IF(Revenue!G10=0,"",Revenue!G7/Revenue!G10) -> 0.38617115 | I23: =IF(Revenue!H10=0,"",Revenue!H7/Revenue!H10) -> 0.37706189 | J23: =IF(Revenue!I10=0,"",Revenue!I7/Revenue!I10) -> 0.37068588 | ... M23: =IF(Revenue!L10=0,"",Revenue!L7/Revenue!L10) -> 0.24636554
B24: PBT margin (level) | C24: =IF(Revenue!B10=0,"",Revenue!B115/Revenue!B10) -> 0.16617901 | D24: =IF(Revenue!C10=0,"",Revenue!C115/Revenue!C10) -> 0.16829156 | E24: =IF(Revenue!D10=0,"",Revenue!D115/Revenue!D10) -> 0.17644606 | F24: =IF(Revenue!E10=0,"",Revenue!E115/Revenue!E10) -> 0.17772555 | G24: =IF(Revenue!F10=0,"",Revenue!F115/Revenue!F10) -> 0.17410509 | H24: =IF(Revenue!G10=0,"",Revenue!G115/Revenue!G10) -> 0.17490224 | I24: =IF(Revenue!H10=0,"",Revenue!H115/Revenue!H10) -> 0.17612824 | J24: =IF(Revenue!I10=0,"",Revenue!I115/Revenue!I10) -> 0.18731951 | ... M24: =IF(Revenue!L10=0,"",Revenue!L115/Revenue!L10) -> 0.1638863
B26: B. QUARTERLY (VND bn; % = YoY vs same quarter prior year)
B27: Metric | C27: 1Q23 | D27: 2Q23 | E27: 3Q23 | F27: 4Q23 | G27: 1Q24 | H27: 2Q24 | I27: 3Q24 | J27: 4Q24 | K27: 1Q25 | L27: 2Q25 | M27: 3Q25 | N27: 4Q25
B28: Total net revenue | C28: =IF(Revenue!AQ10=0,"",Revenue!AQ10) -> 11687.891 | D28: =IF(Revenue!AR10=0,"",Revenue!AR10) -> 12478.109 | E28: =IF(Revenue!AS10=0,"",Revenue!AS10) -> 13761 | F28: =IF(Revenue!AT10=0,"",Revenue!AT10) -> 14691 | G28: =IF(Revenue!AU10=0,"",Revenue!AU10) -> 14092 | H28: =IF(Revenue!AV10=0,"",Revenue!AV10) -> 15246 | I28: =IF(Revenue!AW10=0,"",Revenue!AW10) -> 15903 | J28: =IF(Revenue!AX10=0,"",Revenue!AX10) -> 17608 | ... N28: =IF(Revenue!BB10=0,"",Revenue!BB10) -> 16058
B29: % YoY | C29: =IF(OR(Revenue!AQ10=0,Revenue!AM10=0),"",Revenue!AQ10/Revenue!AM10-1) -> 0.20119076 | D29: =IF(OR(Revenue!AR10=0,Revenue!AN10=0),"",Revenue!AR10/Revenue!AN10-1) -> 0.23593846 | E29: =IF(OR(Revenue!AS10=0,Revenue!AO10=0),"",Revenue!AS10/Revenue!AO10-1) -> 0.23432992 | F29: =IF(OR(Revenue!AT10=0,Revenue!AP10=0),"",Revenue!AT10/Revenue!AP10-1) -> 0.12640085 | G29: =IF(OR(Revenue!AU10=0,Revenue!AQ10=0),"",Revenue!AU10/Revenue!AQ10-1) -> 0.20569228 | H29: =IF(OR(Revenue!AV10=0,Revenue!AR10=0),"",Revenue!AV10/Revenue!AR10-1) -> 0.22181975 | I29: =IF(OR(Revenue!AW10=0,Revenue!AS10=0),"",Revenue!AW10/Revenue!AS10-1) -> 0.15565729 | J29: =IF(OR(Revenue!AX10=0,Revenue!AT10=0),"",Revenue!AX10/Revenue!AT10-1) -> 0.19855694 | ... N29: =IF(OR(Revenue!BB10=0,Revenue!AX10=0),"",Revenue!BB10/Revenue!AX10-1) -> -0.088028169
B30: Technology (Total IT services) | C30: =IF(Revenue!AQ11=0,"",Revenue!AQ11) -> 6844.791 | D30: =IF(Revenue!AR11=0,"",Revenue!AR11) -> 7357.209 | E30: =IF(Revenue!AS11=0,"",Revenue!AS11) -> 8315 | F30: =IF(Revenue!AT11=0,"",Revenue!AT11) -> 8932 | G30: =IF(Revenue!AU11=0,"",Revenue!AU11) -> 8471 | H30: =IF(Revenue!AV11=0,"",Revenue!AV11) -> 9606 | I30: =IF(Revenue!AW11=0,"",Revenue!AW11) -> 9887 | J30: =IF(Revenue!AX11=0,"",Revenue!AX11) -> 11146 | ... N30: =IF(Revenue!BB11=0,"",Revenue!BB11) -> 13526
B31: % YoY | C31: =IF(OR(Revenue!AQ11=0,Revenue!AM11=0),"",Revenue!AQ11/Revenue!AM11-1) -> 0.21337619 | D31: =IF(OR(Revenue!AR11=0,Revenue!AN11=0),"",Revenue!AR11/Revenue!AN11-1) -> 0.28771297 | E31: =IF(OR(Revenue!AS11=0,Revenue!AO11=0),"",Revenue!AS11/Revenue!AO11-1) -> 0.26675788 | F31: =IF(OR(Revenue!AT11=0,Revenue!AP11=0),"",Revenue!AT11/Revenue!AP11-1) -> 0.13752024 | G31: =IF(OR(Revenue!AU11=0,Revenue!AQ11=0),"",Revenue!AU11/Revenue!AQ11-1) -> 0.23758344 | H31: =IF(OR(Revenue!AV11=0,Revenue!AR11=0),"",Revenue!AV11/Revenue!AR11-1) -> 0.30565816 | I31: =IF(OR(Revenue!AW11=0,Revenue!AS11=0),"",Revenue!AW11/Revenue!AS11-1) -> 0.18905592 | J31: =IF(OR(Revenue!AX11=0,Revenue!AT11=0),"",Revenue!AX11/Revenue!AT11-1) -> 0.24787282 | ... N31: =IF(OR(Revenue!BB11=0,Revenue!AX11=0),"",Revenue!BB11/Revenue!AX11-1) -> 0.21352952
B32: Global IT (foreign) | C32: =IF(Revenue!AQ12=0,"",Revenue!AQ12) -> 5437.791 | D32: =IF(Revenue!AR12=0,"",Revenue!AR12) -> 5789.209 | E32: =IF(Revenue!AS12=0,"",Revenue!AS12) -> 6399 | F32: =IF(Revenue!AT12=0,"",Revenue!AT12) -> 6662 | G32: =IF(Revenue!AU12=0,"",Revenue!AU12) -> 6999 | H32: =IF(Revenue!AV12=0,"",Revenue!AV12) -> 7574 | I32: =IF(Revenue!AW12=0,"",Revenue!AW12) -> 8095 | J32: =IF(Revenue!AX12=0,"",Revenue!AX12) -> 8285 | ... N32: =IF(Revenue!BB12=0,"",Revenue!BB12) -> 9808
B33: % YoY | C33: =IF(OR(Revenue!AQ12=0,Revenue!AM12=0),"",Revenue!AQ12/Revenue!AM12-1) -> 0.32262359 | D33: =IF(OR(Revenue!AR12=0,Revenue!AN12=0),"",Revenue!AR12/Revenue!AN12-1) -> 0.28343347 | E33: =IF(OR(Revenue!AS12=0,Revenue!AO12=0),"",Revenue!AS12/Revenue!AO12-1) -> 0.31746826 | F33: =IF(OR(Revenue!AT12=0,Revenue!AP12=0),"",Revenue!AT12/Revenue!AP12-1) -> 0.2237022 | G33: =IF(OR(Revenue!AU12=0,Revenue!AQ12=0),"",Revenue!AU12/Revenue!AQ12-1) -> 0.28710353 | H33: =IF(OR(Revenue!AV12=0,Revenue!AR12=0),"",Revenue!AV12/Revenue!AR12-1) -> 0.30829618 | I33: =IF(OR(Revenue!AW12=0,Revenue!AS12=0),"",Revenue!AW12/Revenue!AS12-1) -> 0.26504141 | J33: =IF(OR(Revenue!AX12=0,Revenue!AT12=0),"",Revenue!AX12/Revenue!AT12-1) -> 0.24362053 | ... N33: =IF(OR(Revenue!BB12=0,Revenue!AX12=0),"",Revenue!BB12/Revenue!AX12-1) -> 0.18382619
B34: Domestic IT | C34: =IF(Revenue!AQ13=0,"",Revenue!AQ13) -> 1407 | D34: =IF(Revenue!AR13=0,"",Revenue!AR13) -> 1568 | E34: =IF(Revenue!AS13=0,"",Revenue!AS13) -> 1916 | F34: =IF(Revenue!AT13=0,"",Revenue!AT13) -> 2270 | G34: =IF(Revenue!AU13=0,"",Revenue!AU13) -> 1472 | H34: =IF(Revenue!AV13=0,"",Revenue!AV13) -> 2032 | I34: =IF(Revenue!AW13=0,"",Revenue!AW13) -> 1792 | J34: =IF(Revenue!AX13=0,"",Revenue!AX13) -> 2861 | ... N34: =IF(Revenue!BB13=0,"",Revenue!BB13) -> 3717
B35: % YoY | C35: =IF(OR(Revenue!AQ13=0,Revenue!AM13=0),"",Revenue!AQ13/Revenue!AM13-1) -> -0.080238863 | D35: =IF(OR(Revenue!AR13=0,Revenue!AN13=0),"",Revenue!AR13/Revenue!AN13-1) -> 0.30376362 | E35: =IF(OR(Revenue!AS13=0,Revenue!AO13=0),"",Revenue!AS13/Revenue!AO13-1) -> 0.12246464 | F35: =IF(OR(Revenue!AT13=0,Revenue!AP13=0),"",Revenue!AT13/Revenue!AP13-1) -> -0.057321889 | G35: =IF(OR(Revenue!AU13=0,Revenue!AQ13=0),"",Revenue!AU13/Revenue!AQ13-1) -> 0.046197584 | H35: =IF(OR(Revenue!AV13=0,Revenue!AR13=0),"",Revenue!AV13/Revenue!AR13-1) -> 0.29591837 | I35: =IF(OR(Revenue!AW13=0,Revenue!AS13=0),"",Revenue!AW13/Revenue!AS13-1) -> -0.064718163 | J35: =IF(OR(Revenue!AX13=0,Revenue!AT13=0),"",Revenue!AX13/Revenue!AT13-1) -> 0.26035242 | ... N35: =IF(OR(Revenue!BB13=0,Revenue!AX13=0),"",Revenue!BB13/Revenue!AX13-1) -> 0.29919609
B36: Telecom | C36: =IF(Revenue!AQ14=0,"",Revenue!AQ14) -> 3790.224 | D36: =IF(Revenue!AR14=0,"",Revenue!AR14) -> 3891.776 | E36: =IF(Revenue!AS14=0,"",Revenue!AS14) -> 4008 | F36: =IF(Revenue!AT14=0,"",Revenue!AT14) -> 4116 | G36: =IF(Revenue!AU14=0,"",Revenue!AU14) -> 4012 | H36: =IF(Revenue!AV14=0,"",Revenue!AV14) -> 4232 | I36: =IF(Revenue!AW14=0,"",Revenue!AW14) -> 4556 | J36: =IF(Revenue!AX14=0,"",Revenue!AX14) -> 4810 | ... N36: =IF(Revenue!BB14=0,"",Revenue!BB14) -> 5220
B37: % YoY | C37: =IF(OR(Revenue!AQ14=0,Revenue!AM14=0),"",Revenue!AQ14/Revenue!AM14-1) -> 0.091928933 | D37: =IF(OR(Revenue!AR14=0,Revenue!AN14=0),"",Revenue!AR14/Revenue!AN14-1) -> 0.07938843 | E37: =IF(OR(Revenue!AS14=0,Revenue!AO14=0),"",Revenue!AS14/Revenue!AO14-1) -> 0.07435974 | F37: =IF(OR(Revenue!AT14=0,Revenue!AP14=0),"",Revenue!AT14/Revenue!AP14-1) -> 0.049360212 | G37: =IF(OR(Revenue!AU14=0,Revenue!AQ14=0),"",Revenue!AU14/Revenue!AQ14-1) -> 0.058512637 | H37: =IF(OR(Revenue!AV14=0,Revenue!AR14=0),"",Revenue!AV14/Revenue!AR14-1) -> 0.08742127 | I37: =IF(OR(Revenue!AW14=0,Revenue!AS14=0),"",Revenue!AW14/Revenue!AS14-1) -> 0.13672655 | J37: =IF(OR(Revenue!AX14=0,Revenue!AT14=0),"",Revenue!AX14/Revenue!AT14-1) -> 0.1686103 | ... N37: =IF(OR(Revenue!BB14=0,Revenue!AX14=0),"",Revenue!BB14/Revenue!AX14-1) -> 0.085239085
B38: Education, Investment & others | C38: =IF(Revenue!AQ17=0,"",Revenue!AQ17) -> 1052.876 | D38: =IF(Revenue!AR17=0,"",Revenue!AR17) -> 1228.124 | E38: =IF(Revenue!AS17=0,"",Revenue!AS17) -> 1439 | F38: =IF(Revenue!AT17=0,"",Revenue!AT17) -> 1643 | G38: =IF(Revenue!AU17=0,"",Revenue!AU17) -> 1609 | H38: =IF(Revenue!AV17=0,"",Revenue!AV17) -> 1408 | I38: =IF(Revenue!AW17=0,"",Revenue!AW17) -> 1460 | J38: =IF(Revenue!AX17=0,"",Revenue!AX17) -> 1652 | ... N38: =IF(Revenue!BB17=0,"",Revenue!BB17) -> 1481
B39: % YoY | C39: =IF(OR(Revenue!AQ17=0,Revenue!AM17=0),"",Revenue!AQ17/Revenue!AM17-1) -> 0.70364193 | D39: =IF(OR(Revenue!AR17=0,Revenue!AN17=0),"",Revenue!AR17/Revenue!AN17-1) -> 0.58033258 | E39: =IF(OR(Revenue!AS17=0,Revenue!AO17=0),"",Revenue!AS17/Revenue!AO17-1) -> 0.6850827 | F39: =IF(OR(Revenue!AT17=0,Revenue!AP17=0),"",Revenue!AT17/Revenue!AP17-1) -> 0.29587595 | G39: =IF(OR(Revenue!AU17=0,Revenue!AQ17=0),"",Revenue!AU17/Revenue!AQ17-1) -> 0.52819515 | H39: =IF(OR(Revenue!AV17=0,Revenue!AR17=0),"",Revenue!AV17/Revenue!AR17-1) -> 0.14646404 | I39: =IF(OR(Revenue!AW17=0,Revenue!AS17=0),"",Revenue!AW17/Revenue!AS17-1) -> 0.014593468 | J39: =IF(OR(Revenue!AX17=0,Revenue!AT17=0),"",Revenue!AX17/Revenue!AT17-1) -> 0.0054777845 | ... N39: =IF(OR(Revenue!BB17=0,Revenue!AX17=0),"",Revenue!BB17/Revenue!AX17-1) -> -0.1035109
B40: Gross profit | C40: =IF(Revenue!AQ7=0,"",Revenue!AQ7) -> 4567.879 | D40: =IF(Revenue!AR7=0,"",Revenue!AR7) -> 4633.8243 | E40: =IF(Revenue!AS7=0,"",Revenue!AS7) -> 5496.369 | F40: =IF(Revenue!AT7=0,"",Revenue!AT7) -> 5631.8636 | G40: =IF(Revenue!AU7=0,"",Revenue!AU7) -> 5510.4657 | H40: =IF(Revenue!AV7=0,"",Revenue!AV7) -> 5651.3573 | I40: =IF(Revenue!AW7=0,"",Revenue!AW7) -> 6158.9557 | J40: =IF(Revenue!AX7=0,"",Revenue!AX7) -> 6377.57 | ... N40: =IF(Revenue!BB7=0,"",Revenue!BB7) -> 7047.2751
B41: % YoY | C41: =IF(OR(Revenue!AQ7=0,Revenue!AM7=0),"",Revenue!AQ7/Revenue!AM7-1) -> 0.15545352 | D41: =IF(OR(Revenue!AR7=0,Revenue!AN7=0),"",Revenue!AR7/Revenue!AN7-1) -> 0.20588085 | E41: =IF(OR(Revenue!AS7=0,Revenue!AO7=0),"",Revenue!AS7/Revenue!AO7-1) -> 0.26078381 | F41: =IF(OR(Revenue!AT7=0,Revenue!AP7=0),"",Revenue!AT7/Revenue!AP7-1) -> 0.074521918 | G41: =IF(OR(Revenue!AU7=0,Revenue!AQ7=0),"",Revenue!AU7/Revenue!AQ7-1) -> 0.20635106 | H41: =IF(OR(Revenue!AV7=0,Revenue!AR7=0),"",Revenue!AV7/Revenue!AR7-1) -> 0.21958817 | I41: =IF(OR(Revenue!AW7=0,Revenue!AS7=0),"",Revenue!AW7/Revenue!AS7-1) -> 0.12054989 | J41: =IF(OR(Revenue!AX7=0,Revenue!AT7=0),"",Revenue!AX7/Revenue!AT7-1) -> 0.13240847 | ... N41: =IF(OR(Revenue!BB7=0,Revenue!AX7=0),"",Revenue!BB7/Revenue!AX7-1) -> 0.10500945
B42: Profit before tax (PBT) | C42: =IF(Revenue!AQ115=0,"",Revenue!AQ115) -> 2120.643 | D42: =IF(Revenue!AR115=0,"",Revenue!AR115) -> 2218.357 | E42: =IF(Revenue!AS115=0,"",Revenue!AS115) -> 2429 | F42: =IF(Revenue!AT115=0,"",Revenue!AT115) -> 2435 | G42: =IF(Revenue!AU115=0,"",Revenue!AU115) -> 2534 | H42: =IF(Revenue!AV115=0,"",Revenue!AV115) -> 2663 | I42: =IF(Revenue!AW115=0,"",Revenue!AW115) -> 2914 | J42: =IF(Revenue!AX115=0,"",Revenue!AX115) -> 2960 | ... N42: =IF(Revenue!BB115=0,"",Revenue!BB115) -> 3499
...

Sheet Scenarios
B1: FPT VN Equity
B2: Revenue growth, margins, income
B5: SCENARIO SWITCH | E5: 1
G6: 2025 | H6: 2026F | I6: 2027F | J6: 2028F | M6: Kịch bản | N6: Giả định vĩ mô & doanh nghiệp | O6: Doanh thu CAGR (2025–2028F) | P6: Biên LNST TB | Q6: LNST CAGR | R6: Rủi ro / Yếu tố hỗ trợ
A7: 1 | B7: IT Revenue Growth
B9: Global IT Revenue Growth | G9: =OFFSET(G10,$E$5,0) -> -3.2307046e-05 | H9: =OFFSET(H10,$E$5,0) -> 0.14668042 | I9: =OFFSET(I10,$E$5,0) -> 0.16651158 | J9: =OFFSET(J10,$E$5,0) -> 0.17659111
C11: Base case | G11: =Revenue!N169 -> -3.2307046e-05 | H11: =Revenue!J169 -> 0.14668042 | I11: =Revenue!K169 -> 0.16651158 | J11: =Revenue!L169 -> 0.17659111 | M11: 🔻 Tiêu cực | N11: Chi tiêu CNTT toàn cầu chững lại Lạm phát lương, tỷ giá bất lợi GDP VN ~5.5% | O11: ~15.6% | P11: ~14.9% | Q11: ~14.5% | R11: Biên lợi nhuận thu hẹp, biến động tỷ giá
C12: Worst case | G12: 0.18 | H12: 0.22 | I12: 0.201 | J12: 0.196 | M12: 🟢 Cơ sở | N12: Vĩ mô ổn định, tỷ giá trung lập Khách hàng tiếp tục mở rộng GDP VN ~6.2% | O12: ~17.8% | P12: ~15.9% | Q12: ~17.6% | R12: Phù hợp xu hướng lịch sử & kế hoạch công ty
C13: Best case | G13: 0.23 | H13: 0.24 | I13: 0.242 | J13: 0.238 | M13: 🔼 Tích cực | N13: Chu kỳ công nghệ phục hồi Tăng giá bán, tỷ giá thuận lợi GDP VN ~7% | O13: ~20.1% | P13: ~16.5% | Q13: ~20.1% | R13: Hợp đồng lớn, hiệu suất cải thiện
B15: Domestic IT Revenue Growth | G15: =OFFSET(G16,$E$5,0) -> 0.09 | H15: =OFFSET(H16,$E$5,0) -> 0.12 | I15: =OFFSET(I16,$E$5,0) -> 0.12 | J15: =OFFSET(J16,$E$5,0) -> 0.12
C17: =$C$11 -> Base case | G17: 0.09 | H17: 0.126858 | I17: 0.12 | J17: 0.12
C18: =$C$12 -> Worst case | G18: 0.05 | H18: 0.11 | I18: 0.1 | J18: 0.1
C19: =$C$13 -> Best case | G19: 0.12 | H19: 0.15 | I19: 0.14 | J19: 0.13
A21: 2 | B21: Telecom & Education Revenue Growth
B22: Telecom Revenue Growth | G22: =OFFSET(G23,$E$5,0) -> 0.12 | H22: =OFFSET(H23,$E$5,0) -> 0.115 | I22: =OFFSET(I23,$E$5,0) -> 0.12 | J22: =OFFSET(J23,$E$5,0) -> 0.12
C24: =$C$11 -> Base case | G24: 0.12 | H24: 0.115 | I24: 0.12 | J24: 0.12
C25: =$C$12 -> Worst case | G25: 0.12 | H25: 0.115 | I25: 0.113 | J25: 0.11
C26: =$C$13 -> Best case | G26: 0.15 | H26: 0.13 | I26: 0.135 | J26: 0.135
A28: 3 | B28: Education Revenue Growth | G28: =OFFSET(G29,$E$5,0) -> 0.1 | H28: =OFFSET(H29,$E$5,0) -> 0.05 | I28: =OFFSET(I29,$E$5,0) -> 0.12 | J28: =OFFSET(J29,$E$5,0) -> 0.12
C30: =$C$11 -> Base case | G30: 0.1 | H30: 0.05 | I30: 0.12 | J30: 0.12
C31: Worst case: +5.0% | G31: 0.13 | H31: 0.127 | I31: 0.124 | J31: 0.12
C32: Best case: -5.0% | G32: 0.16 | H32: 0.15 | I32: 0.14 | J32: 0.13
A42: 5 | B42: JVs income/ Revenue
B43: Average growth rate | G43: =OFFSET(G44,$E$5,0) -> 0.01 | H43: =OFFSET(H44,$E$5,0) -> 0.05 | I43: =OFFSET(I44,$E$5,0) -> 0.047 | J43: =OFFSET(J44,$E$5,0) -> 0.047
C45: =$C$11 -> Base case | G45: 0.01 | H45: 0.045525 | I45: 0.047578 | J45: 0.052837
C46: =$C$12 -> Worst case | G46: 0.002 | H46: 0.002 | I46: 0.002 | J46: 0.002
C47: =$C$13 -> Best case | G47: 0.01 | H47: 0.01 | I47: 0.01 | J47: 0.01
C52: Dự phóng : Kịch bản cơ sở
C53: Doanh thu: Kịch bản | E53: 2025F | F53: 2026F | G53: 2027F | H53: 2028F
C54: Doanh thu CNTT nước ngoài | D54: (VNDbn) | E54: =Revenue!N12 -> 30952 | F54: =Revenue!J12 -> 40571.847 | G54: =Revenue!K12 -> 47327.529 | H54: =Revenue!L12 -> 55685.15
C55: Doanh thu CNTT trong nước | D55: (VNDbn) | E55: =Revenue!N13 -> 8891.13 | F55: =Revenue!J13 -> 10184.16 | G55: =Revenue!K13 -> 11406.259 | H55: =Revenue!L13 -> 12775.01
C56: Doanh thu viễn thông | D56: (VNDbn) | E56: =Revenue!N14 -> 19723.2 | F56: =Revenue!J14 -> 21750.305 | G56: =Revenue!K14 -> 24360.342 | H56: =Revenue!L14 -> 27283.583
C57: Doanh thu giáo dục | D57: (VNDbn) | E57: =Revenue!N17 -> 6741.9 | F57: =Revenue!J17 -> 6438.6 | G57: =Revenue!K17 -> 7211.232 | H57: =Revenue!L17 -> 8076.5798
C58: Tổng doanh thu | D58: (VNDbn) | E58: =Revenue!N10 -> 66308.23 | F58: =Revenue!J10 -> 78944.912 | G58: =Revenue!K10 -> 90305.362 | H58: =Revenue!L10 -> 103820.32
E59: =E58/PL!O9-1 -> 0.05504386 | F59: =F58/E58-1 -> 0.19057486 | G59: =G58/F58-1 -> 0.14390351 | H59: =H58/G58-1 -> 0.14965845
C61: Summary values: Kịch bản | E61: 2025F | F61: 2026F | G61: 2027F | H61: 2028F
C62: Doanh thu | D62: (VNDbn) | E62: =Revenue!N3 -> 66308.23 | F62: =Revenue!J3 -> 78944.912 | G62: =Revenue!K3 -> 90305.362 | H62: =Revenue!L3 -> 103820.32
C63: LN gộp | D63: (VNDbn) | E63: =PL!W13 -> 24854.645 | F63: =PL!Q13 -> 19823.725 | G63: =PL!R13 -> 22276.608 | H63: =PL!S13 -> 25577.75
C64: LNHĐKD | D64: (VNDbn) | E64: =PL!W24 -> 10266.834 | F64: =PL!Q24 -> 9757.474 | G64: =PL!R24 -> 10802.175 | H64: =PL!S24 -> 12260.357
C65: Biên LNHĐ | D65: (%) | E65: =PL!W26 -> 0.15483499 | F65: =PL!Q26 -> 0.17060129 | G65: =PL!R26 -> 0.16380577 | H65: =PL!S26 -> 0.16018917
...

Sheet Revenue
A1: VNDbn | B1: 2018 | C1: =B1+1 -> 2019 | D1: 2020 | E1: 2021 | F1: 2022 | G1: 2023 | H1: 2024 | I1: 2025 | J1: 2026F | K1: 2027F | L1: 2028F | N1: 2025F | O1: 2024 | V1: QUARTER REPORT | Z1: 4Q18 | AA1: Q1/19 | AB1: Q2/19 | AC1: Q3/19 | AD1: 4Q19 | AE1: Q1/20 | AF1: Q2/20 | AG1: Q3/20 | AH1: 4Q20 | AI1: 1Q21 | AJ1: 2Q21 | AK1: 3Q21 | AL1: 4Q21 | AM1: 1Q22 | AN1: 2Q22 | AO1: 3Q22 | AP1: 4Q22 | AQ1: 1Q23 | AR1: 2Q23 | AS1: 3Q23 | AT1: 4Q23 | AU1: 1Q24 | AV1: 2Q24 | AW1: 3Q24 | AX1: 4Q24 | AY1: 1Q25 | AZ1: 2Q25 | BA1: 3Q25 | BB1: 4Q25 | BC1: 1Q26 | BD1: 6M23 | BE1: 6M24 | BF1: 7M24 | BG1: 8M24 | BH1: 9M24 | BI1: 6M25 | BJ1: 7M25 | BK1: 8M25 | BL1: 9M25 | BP1: 6M26 | BQ1: 2Q26 | CC1: H1/19 | CD1: H1/20 | CE1: H1/21 | CF1: H1/22 | CG1: H1/23 | CH1: 9M23 | CI1: YoY growth | CJ1: H2/19 | CK1: H2/20 | CL1: H2/21 | CM1: H2/22 | CN1: H2/23 | CP1: 8M/2022 | CQ1: 8M/2023
A2: Total net revenue (post-deconsolidation) | B2: =B3-B14 -> 14382.534 | C2: =C3-C14 -> 17318.533 | D2: =D3-D14 -> 18364.247 | E2: =E3-E14 -> 22970.847 | F2: =F3-F14 -> 29279.879 | G2: =G3-G14 -> 36811.901 | H2: =H3-H14 -> 45238.79 | I2: 50605.83 | J2: =J3-J14 -> 57194.607 | K2: =K3-K14 -> 65945.02 | L2: =L3-L14 -> 76536.74 | N2: =N9 -> 0 | O2: =O9 -> 0 | AE2: =PL!BO8 -> 0.0021744814 | AF2: =PL!BP8 -> 0.0024668202 | AG2: =PL!BQ8 -> 0.0033729491 | AH2: =PL!BR8 -> 0.0039105489 | AI2: =PL!BS8 -> 0.0025437597 | AJ2: =PL!BT8 -> -0.0018784805 | AK2: =PL!BU8 -> -0.0043884108 | AL2: =PL!BV8 -> 0.0010001896 | ... BB2: =PL!CL8 -> 0.0016494397 | CD2: =AE2+AF2 -> 0.0046413016 | CP2: 27060 | CQ2: 32827
A3: Total net revenue | B3: =PL!I9 -> 23213.537 | C3: =PL!J9 -> 27716.96 | D3: =PL!K9 -> 29830.401 | E3: =PL!L9 -> 35657.263 | F3: =PL!M9 -> 44009.528 | G3: =PL!N9 -> 52617.901 | H3: =PL!O9 -> 62848.79 | I3: =PL!P9 -> 70207.69 | J3: =J10 -> 78944.912 | K3: =K10 -> 90305.362 | L3: =L10 -> 103820.32 | N3: =N10 -> 66308.23 | O3: =O10 -> 55744.61 | AE3: =PL!BO9 -> 6630.5649 | AF3: =PL!BP9 -> 6980.0025 | AG3: =PL!BQ9 -> 7553.1285 | AH3: =PL!BR9 -> 8666.7046 | AI3: =PL!BS9 -> 7586.3277 | AJ3: =PL!BT9 -> 8641.7073 | AK3: =PL!BU9 -> 8725.172 | AL3: =PL!BV9 -> 10704.056 | ... BB3: =PL!CL9 -> 20225.45 | BC3: 12480 | BD3: =BC3*4 -> 49920 | BP3: 26269 | BQ3: =BP3-BC3 -> 13789 | CD3: =AE3+AF3 -> 13610.567 | CP3: 27060 | CQ3: 32827
A4: % growth | B4: =PL!I10 -> -0.45582999 | C4: =C3/B3-1 -> 0.19399988 | D4: =D3/C3-1 -> 0.0762508 | E4: =E3/D3-1 -> 0.19533301 | F4: =F3/E3-1 -> 0.23423742 | G4: =G3/F3-1 -> 0.19560249 | H4: =H3/G3-1 -> 0.19443743 | I4: =I3/H3-1 -> 0.11708897 | J4: =J3/I3-1 -> 0.12444821 | ... L4: =L3/K3-1 -> 0.14965845 | N4: =N3/H3-1 -> 0.05504386 | O4: =O3/G3-1 -> 0.059422917 | AE4: =AE3/AA3-1 -> #DIV/0! | AF4: =AF3/AB3-1 -> #DIV/0! | AG4: =AG3/AC3-1 -> #DIV/0! | AH4: =AH3/AD3-1 -> #DIV/0! | AI4: =AI3/AE3-1 -> 0.144145 | AJ4: =AJ3/AF3-1 -> 0.2380665 | AK4: =AK3/AG3-1 -> 0.15517324 | AL4: =AL3/AH3-1 -> 0.23507793 | ... BB4: =BB3/AX3-1 -> 0.14866292 | CQ4: =CQ3/CP3-1 -> 0.21311899
A5: Total COGS | B5: =PL!I11 -> 14490.658 | C5: =PL!J11 -> 17004.911 | D5: =PL!K11 -> 18016.743 | E5: =PL!L11 -> 22025.298 | F5: =PL!M11 -> 26842.249 | G5: =PL!N11 -> 32298.347 | H5: =PL!O11 -> 39150.45 | I5: =PL!P11 -> 44217.42 | J5: =J57 -> 37370.882 | K5: =K57 -> 43668.412 | L5: =L57 -> 50958.99 | M5: =J2*66% -> 37748.44 | N5: =N57 -> 41453.585 | O5: =O57 -> 36150.136 | AE5: =PL!BO11 -> 4006.1865 | AF5: =PL!BP11 -> 4258.2478 | AG5: =PL!BQ11 -> 4554.3503 | AH5: =PL!BR11 -> 5195.7837 | AI5: =PL!BS11 -> 4691.8007 | AJ5: =PL!BT11 -> 5201.5261 | AK5: =PL!BU11 -> 5474.2432 | AL5: =PL!BV11 -> 6609.6875 | ... BB5: =PL!CL11 -> 13178.175 | CD5: =AE5+AF5 -> 8264.4344 | CF5: =SUM(AM5:AN5) -> 12030.304
A6: % revenue | B6: =B5/B3 -> 0.62423309 | C6: =C5/C3 -> 0.61352004 | D6: =D5/D3 -> 0.60397255 | E6: =E5/E3 -> 0.61769459 | F6: =F5/F3 -> 0.60991904 | G6: =G5/G3 -> 0.61382812 | H6: =H5/H3 -> 0.62293085 | I6: =I5/I3 -> 0.62980879 | J6: =J5/J2 -> 0.65339871 | K6: =K5/K3 -> 0.48356389 | L6: =L5/L3 -> 0.4908383 | N6: =N5/N3 -> 0.62516501 | O6: =O5/O3 -> 0.64849563 | S6: 7913 | T6: =S6/S8-1 -> 0.22777347 | AE6: =AE5/AA5-1 -> #DIV/0! | AF6: =AF5/AB5-1 -> #DIV/0! | AG6: =AG5/AC5-1 -> #DIV/0! | AH6: =AH5/AD5-1 -> #DIV/0! | AI6: =AI5/AE5-1 -> 0.17113886 | AJ6: =AJ5/AF5-1 -> 0.22151795 | AK6: =AK5/AG5-1 -> 0.20198115 | AL6: =AL5/AH5-1 -> 0.27212522 | ... BB6: =BB5/AX5-1 -> 0.17345338
A7: Total gross profit | B7: =B3-B5 -> 8722.879 | C7: =C3-C5 -> 10712.05 | D7: =D3-D5 -> 11813.657 | E7: =E3-E5 -> 13631.964 | F7: =F3-F5 -> 17167.279 | G7: =G3-G5 -> 20319.553 | H7: =H3-H5 -> 23698.34 | I7: =I3-I5 -> 25990.27 | J7: =J2-J5 -> 19823.725 | K7: =K2-K5 -> 22276.608 | L7: =L2-L5 -> 25577.75 | N7: =N3-N5 -> 24854.645 | O7: =O3-O5 -> 19594.474 | S7: 1038 | T7: =S7/S9-1 -> 0.24759615 | AE7: =PL!BO13 -> 2624.3784 | AF7: =PL!BP13 -> 2721.7547 | AG7: =PL!BQ13 -> 2998.7782 | AH7: =PL!BR13 -> 3470.921 | AI7: =PL!BS13 -> 2894.527 | AJ7: =PL!BT13 -> 3440.1811 | AK7: =PL!BU13 -> 3250.9287 | AL7: =PL!BV13 -> 4094.3682 | ... BB7: =PL!CL13 -> 7047.2751 | CD7: =AE7+AF7 -> 5346.1331
A8: % margin | B8: =B7/B3 -> 0.37576691 | C8: =C7/C3 -> 0.38647996 | D8: =D7/D3 -> 0.39602745 | E8: =E7/E3 -> 0.38230541 | F8: =F7/F3 -> 0.39008096 | G8: =G7/G3 -> 0.38617188 | H8: =H7/H3 -> 0.37706915 | I8: =I7/I2 -> 0.51358253 | J8: =J7/J2 -> 0.34660129 | K8: =K7/K2 -> 0.33780577 | L8: =L7/L2 -> 0.33418917 | N8: =N7/N3 -> 0.37483499 | O8: =O7/O3 -> 0.35150437 | Q8: 56404 | R8: 62849 | S8: =R8-Q8 -> 6445 | AE8: =PL!BO14 -> 0.39580012 | AF8: =PL!BP14 -> 0.38993606 | AG8: =PL!BQ14 -> 0.39702465 | AH8: =PL!BR14 -> 0.40048913 | AI8: =PL!BS14 -> 0.38154521 | AJ8: =PL!BT14 -> 0.39809045 | AK8: =PL!BU14 -> 0.37259194 | AL8: =PL!BV14 -> 0.38250625 | ... BB8: =PL!CL14 -> 0.34843601
Q9: 10239 | R9: 11071 | S9: =R9-Q9 -> 832 | T9: Achieved/Forecast | U9: FPT's 2024 plan | V9: %23/Plan
A10: Net revenue | B10: =SUM(B12:B13,B15:B17) -> 23213.537 | C10: =SUM(C12:C13,C15:C17) -> 27716.96 | D10: =SUM(D12:D13,D15:D17) -> 29830.401 | E10: =SUM(E12:E13,E15:E17) -> 35657.263 | F10: =SUM(F12:F13,F15:F17) -> 44009.528 | G10: =SUM(G12:G13,G15:G17) -> 52618 | H10: =SUM(H12:H13,H15:H17) -> 62850 | I10: =SUM(I12:I13,I15:I17) -> 70114 | J10: =SUM(J11,J14,J17) -> 78944.912 | K10: =SUM(K11,K14,K17) -> 90305.362 | L10: =SUM(L11,L14,L17) -> 103820.32 | N10: =SUM(N11,N14,N17) -> 66308.23 | O10: =SUM(O11,O14,O17) -> 55744.61 | T10: Net revenue | U10: =U11+U12+U13 -> 61850 | AA10: =AA3 -> 0 | AB10: =AB3 -> 0 | AC10: =AC3 -> 0 | AD10: =AD3 -> 0 | AE10: =AE3 -> 6630.5649 | AF10: =AF3 -> 6980.0025 | AG10: =AG3 -> 7553.1285 | AH10: =AH3 -> 8666.7046 | ... AP10: =AP3 -> 13042.426 | AQ10: =SUM(AQ12:AQ13,AQ15:AQ17) -> 11687.891 | AR10: =24166-AQ10 -> 12478.109 | AS10: =37927-AR10-AQ10 -> 13761 | AT10: =52618-AS10-AR10-AQ10 -> 14691 | AU10: =AU11+AU14+AU17 -> 14092 | AV10: =AV11+AV14+AV17 -> 15246 | AW10: =45241-AV10-AU10 -> 15903 | AX10: =62849-AW10-AV10-AU10 -> 17608 | AY10: 16058 | AZ10: =32683-AY10 -> 16625 | BA10: =49887-AZ10-AY10 -> 17204 | BB10: =49887-BA10-AZ10 -> 16058 | BD10: =AQ10+AR10 -> 24166 | BE10: =AU10+AV10 -> 29338 | BI10: =AY10+AZ10 -> 32683 | BL10: =BA10+AZ10+AY10 -> 49887 | BN10: =BI10/N10 -> 0.49289508 | BP10: 26269 | BQ10: =BP10-BC3 -> 13789 | CD10: =AE10+AF10 -> 13610.567 | CE10: =AI10+AJ10 -> 16228.035 | CF10: =AM10+AN10 -> 19826.314 | CG10: =AQ10+AR10 -> 24166
A11: Total IT services | B11: =SUM(B12:B13) -> 13401.574 | C11: =SUM(C12:C13) -> 15783.421 | D11: =SUM(D12:D13) -> 16804.932 | E11: =SUM(E12:E13) -> 20872.244 | F11: =SUM(F12:F13) -> 25762.902 | G11: =31449 -> 31449 | H11: 39110 | I11: 44475 | J11: =SUM(J12,J13) -> 50756.007 | K11: =SUM(K12,K13) -> 58733.788 | L11: =SUM(L12,L13) -> 68460.16 | M11: =J11+J17 -> 57194.607 | N11: =SUM(N12,N13) -> 39843.13 | O11: =SUM(O12,O13) -> 31950.27 | T11: Total IT services | U11: 38150 | AE11: =SUM(AE12:AE13) -> 3594.085 | AF11: =SUM(AF12:AF13) -> 3933.248 | AG11: =SUM(AG12:AG13) -> 4183.63 | AH11: =SUM(AH12:AH13) -> 5093.969 | AI11: =SUM(AI12:AI13) -> 4177.351 | AJ11: =SUM(AJ12:AJ13) -> 4969.317 | AK11: =SUM(AK12:AK13) -> 5237.552 | AL11: =SUM(AL12:AL13) -> 6488.024 | ... AQ11: =SUM(AQ12:AQ13) -> 6844.791 | AR11: =14202-AQ11 -> 7357.209 | AS11: =22517-AR11-AQ11 -> 8315 | AT11: =31449-AS11-AR11-AQ11 -> 8932 | AU11: =AU13+AU12 -> 8471 | AV11: =AV13+AV12 -> 9606 | AW11: =27964-AV11-AU11 -> 9887 | AX11: =39110-AW11-AV11-AU11 -> 11146 | AY11: 9769 | AZ11: =20128-AY11 -> 10359 | BA11: =30949-AZ11-AY11 -> 10821 | BB11: =44475-BA11-AZ11-AY11 -> 13526 | BC11: 10842 | BD11: =AQ11+AR11 -> 14202 | BE11: =AU11+AV11 -> 18077 | BI11: =AY11+AZ11 -> 20128 | BL11: =BA11+AZ11+AY11 -> 30949 | BN11: =BI11/N11 -> 0.50518119 | BP11: 23138 | BQ11: =BP11-BC11 -> 12296 | CD11: =AE11+AF11 -> 7527.333 | CE11: =AI11+AJ11 -> 9146.668 | CF11: =AM11+AN11 -> 11354.504 | CG11: =AQ11+AR11 -> 14202 | CI11: =CG11/CF11-1 -> 0.25078119
A12: Global IT | B12: 8443.472 | C12: 10848.063 | D12: 12000.26 | E12: 14540.801 | F12: 18915.494 | G12: 24288 | H12: 30953 | I12: 35382 | J12: =I12*(1+Scenarios!H9) -> 40571.847 | K12: =J12*(1+Scenarios!I9) -> 47327.529 | L12: =K12*(1+Scenarios!J9) -> 55685.15 | N12: =H12*(1+Scenarios!G9) -> 30952 | O12: =SUM(O159:O162) -> 24288 | T12: Total telecom | U12: 17600 | AE12: 2890.8 | AF12: =5810.278-AE12 -> 2919.478 | AG12: =8778.695-SUM(AE12:AF12) -> 2968.417 | AH12: =12000.26-SUM(AE12:AG12) -> 3221.565 | AI12: 3169.398 | AJ12: 3513.542 | AK12: 3731.633 | AL12: 4126.228 | AM12: 4111.367 | AN12: 4510.72 | AO12: 4857.043 | AP12: 5444.135 | AQ12: 5437.791 | AR12: =11227-AQ12 -> 5789.209 | AS12: =17626-AR12-AQ12 -> 6399 | AT12: =24288-AS12-AR12-AQ12 -> 6662 | AU12: 6999 | AV12: =14573-AU12 -> 7574 | AW12: =22668-AV12-AU12 -> 8095 | AX12: =30953-AW12-AV12-AU12 -> 8285 | AY12: 8186 | AZ12: =16669-AY12 -> 8483 | BA12: =25574-AZ12-AY12 -> 8905 | BB12: =35382-BA12-AZ12-AY12 -> 9808 | BD12: =AQ12+AR12 -> 11227 | BE12: =AU12+AV12 -> 14573 | BI12: =AY12+AZ12 -> 16669 | BL12: =BA12+AZ12+AY12 -> 25574 | BN12: =BI12/N12 -> 0.53854355 | BP12: 18902 | CD12: =AE12+AF12 -> 5810.278 | CE12: =AI12+AJ12 -> 6682.94 | CF12: =AM12+AN12 -> 8622.087 | CG12: =AQ12+AR12 -> 11227 | CI12: =CG12/CF12-1 -> 0.30212094
A13: Domestic IT | B13: 4958.102 | C13: 4935.358 | D13: 4804.672 | E13: 6331.443 | F13: 6847.408 | G13: =G11-G12 -> 7161 | H13: 8157 | I13: 9093 | J13: =I13*(1+Scenarios!H15) -> 10184.16 | K13: =J13*(1+Scenarios!I15) -> 11406.259 | L13: =K13*(1+Scenarios!J15) -> 12775.01 | N13: =H13*(1+Scenarios!G15) -> 8891.13 | O13: =G13*(1+O22) -> 7662.27 | T13: Investment, education & others | U13: 6100 | AE13: 703.285 | AF13: =1717.055-AE13 -> 1013.77 | AG13: =2932.268-SUM(AE13:AF13) -> 1215.213 | AH13: =4804.672-SUM(AE13:AG13) -> 1872.404 | AI13: 1007.953 | AJ13: 1455.775 | AK13: 1505.919 | AL13: 2361.796 | AM13: 1529.745 | AN13: 1202.672 | AO13: 1706.958 | AP13: 2408.033 | AQ13: 1407 | AR13: =2975-AQ13 -> 1568 | AS13: =4891-AR13-AQ13 -> 1916 | AT13: =7161-AS13-AR13-AQ13 -> 2270 | AU13: 1472 | AV13: =3504-AU13 -> 2032 | AW13: =5296-AV13-AU13 -> 1792 | AX13: =8157-AW13-AV13-AU13 -> 2861 | AY13: 1583 | AZ13: =3459-AY13 -> 1876 | BA13: =5376-AZ13-AY13 -> 1917 | BB13: =9093-BA13-AZ13-AY13 -> 3717 | BD13: =AQ13+AR13 -> 2975 | BE13: =AU13+AV13 -> 3504 | BI13: =AY13+AZ13 -> 3459 | BL13: =BA13+AZ13+AY13 -> 5376 | BN13: =BI13/N13 -> 0.38903941 | BP13: 4236 | CD13: =AE13+AF13 -> 1717.055 | CE13: =AI13+AJ13 -> 2463.728 | CF13: =AM13+AN13 -> 2732.417 | CG13: =AQ13+AR13 -> 2975 | CI13: =CG13/CF13-1 -> 0.088779641
A14: Total telecom | B14: =SUM(B15:B16) -> 8831.003 | C14: =SUM(C15:C16) -> 10398.427 | D14: =SUM(D15:D16) -> 11466.154 | E14: =SUM(E15:E16) -> 12686.416 | F14: =SUM(F15:F16) -> 14729.649 | G14: =G15+G16 -> 15806 | H14: 17610 | I14: 19507 | J14: =I14*(1+Scenarios!H24) -> 21750.305 | K14: =J14*(1+Scenarios!I24) -> 24360.342 | L14: =K14*(1+Scenarios!J24) -> 27283.583 | N14: =H14*(1+Scenarios!G24) -> 19723.2 | O14: =SUM(O15:O16) -> 17680.52 | T14: PBT | U14: 10875 | AE14: =SUM(AE15:AE16) -> 2668.02 | AF14: =SUM(AF15:AF16) -> 2770.679 | AG14: =SUM(AG15:AG16) -> 2872.372 | AH14: =SUM(AH15:AH16) -> 3155.083 | AI14: =SUM(AI15:AI16) -> 2925.12 | AJ14: =SUM(AJ15:AJ16) -> 3201.014 | AK14: =SUM(AK15:AK16) -> 3105.698 | AL14: =SUM(AL15:AL16) -> 3454.584 | ... AQ14: =SUM(AQ15:AQ16) -> 3790.224 | AR14: =7682-AQ14 -> 3891.776 | AS14: =11690-AR14-AQ14 -> 4008 | AT14: =15806-AS14-AR14-AQ14 -> 4116 | AU14: =AU15+AU16 -> 4012 | AV14: =AV15+AV16 -> 4232 | AW14: =12800-AV14-AU14 -> 4556 | AX14: =17610-AW14-AV14-AU14 -> 4810 | AY14: 4582 | AZ14: =9357-AY14 -> 4775 | BA14: =14287-AZ14-AY14 -> 4930 | BB14: =19507-AY14-AZ14-BA14 -> 5220 | BD14: =AQ14+AR14 -> 7682 | BE14: =AU14+AV14 -> 8244 | BI14: =AY14+AZ14 -> 9357 | BL14: =BA14+AZ14+AY14 -> 14287 | BN14: =BI14/N14 -> 0.47441592 | CD14: =AE14+AF14 -> 5438.699 | CE14: =AI14+AJ14 -> 6126.134 | CF14: =AM14+AN14 -> 7076.665 | CG14: =AQ14+AR14 -> 7682 | CI14: =CG14/CF14-1 -> 0.085539587
A15: Communication | B15: 8293.162 | C15: 9789.511 | D15: 10867.003 | E15: 12078.678 | F15: 13954.22 | G15: 15186 | H15: 16906 | I15: 18702 | J15: =SUM(J199,J201) -> 20909.325 | K15: =SUM(K199,K201) -> 23355.703 | L15: =SUM(L199,L201) -> 26051.256 | N15: =SUM(N199,N201) -> 19184.84 | O15: =SUM(O199,O201) -> 16998.52 | T15: Total IT services | U15: 5195 | AE15: 2565.155 | AF15: =5217.39-AE15 -> 2652.235 | AG15: =7947.542-SUM(AE15:AF15) -> 2730.152 | AH15: =10867.003-SUM(AE15:AG15) -> 2919.461 | AI15: 2803.634 | AJ15: 3043.648 | AK15: 2974.898 | AL15: 3256.498 | AM15: 3320.123 | AN15: 3406.44 | AO15: 3516.78 | AP15: 3710.877 | AQ15: 3694.996 | AR15: =7423-AQ15 -> 3728.004 | AS15: =11278-AR15-AQ15 -> 3855 | AT15: =15186-AS15-AR15-AQ15 -> 3908 | AU15: 3885 | AV15: =7966-AU15 -> 4081 | AW15: =12320-AV15-AU15 -> 4354 | AX15: =16906-AW15-AV15-AU15 -> 4586 | AY15: 4465 | AZ15: =9030-AY15 -> 4565 | BA15: =13738-AZ15-AY15 -> 4708 | BB15: =18702-AY15-AZ15-BA15 -> 4964 | BD15: =AQ15+AR15 -> 7423 | BE15: =AU15+AV15 -> 7966 | BI15: =AY15+AZ15 -> 9030 | BL15: =BA15+AZ15+AY15 -> 13738 | BN15: =BI15/N15 -> 0.47068414 | CD15: =AE15+AF15 -> 5217.39 | CE15: =AI15+AJ15 -> 5847.282 | CF15: =AM15+AN15 -> 6726.563 | CG15: =AQ15+AR15 -> 7423 | CI15: =CG15/CF15-1 -> 0.10353534
A16: Digital content | B16: 537.841 | C16: 608.916 | D16: 599.151 | E16: 607.738 | F16: 775.429 | G16: 620 | H16: 705 | I16: 805 | J16: =I16*(1+J25) -> 917.7 | K16: =J16*(1+K25) -> 1046.178 | L16: =K16*(1+L25) -> 1192.6429 | N16: =H16*(1+N25) -> 803.7 | O16: =G16*(1+O25) -> 682 | T16: Total telecom | U16: 3508 | AE16: 102.865 | AF16: =221.309-AE16 -> 118.444 | AG16: =363.529-SUM(AE16:AF16) -> 142.22 | AH16: =599.151-SUM(AE16:AG16) -> 235.622 | AI16: 121.486 | AJ16: 157.366 | AK16: 130.8 | AL16: 198.086 | AM16: 151.004 | AN16: 199.098 | AO16: 213.814 | AP16: 211.513 | AQ16: 95.228 | AR16: =259-AQ16 -> 163.772 | AS16: =413-AR16-AQ16 -> 154 | AT16: =620-AS16-AR16-AQ16 -> 207 | AU16: 127 | AV16: =278-AU16 -> 151 | AW16: =480-AV16-AU16 -> 202 | AX16: =705-AW16-AV16-AU16 -> 225 | AY16: 117 | AZ16: =327-AY16 -> 210 | BA16: =549-AZ16-AY16 -> 222 | BB16: =805-AY16-AZ16-BA16 -> 256 | BD16: =AQ16+AR16 -> 259 | BE16: =AU16+AV16 -> 278 | BI16: =AY16+AZ16 -> 327 | BL16: =BA16+AZ16+AY16 -> 549 | BN16: =BI16/N16 -> 0.40686823 | CD16: =AE16+AF16 -> 221.309 | CE16: =AI16+AJ16 -> 278.852 | CF16: =AM16+AN16 -> 350.102 | CG16: =AQ16+AR16 -> 259 | CI16: =CG16/CF16-1 -> -0.26021559
A17: Education, Investments and others | B17: =1375.177-394.217142275 -> 980.95986 | C17: =1792.058-256.945847725005 -> 1535.1122 | D17: =2187.175-627.860473176002 -> 1559.3145 | E17: =3237.52-1138.91745497299 -> 2098.6025 | F17: =5066.948-1549.971319089 -> 3516.9767 | G17: 5363 | H17: 6129 | I17: 6132 | J17: =I17*(1+Scenarios!H28) -> 6438.6 | K17: =J17*(1+Scenarios!I28) -> 7211.232 | L17: =K17*(1+Scenarios!J28) -> 8076.5798 | N17: =H17*(1+Scenarios!G28) -> 6741.9 | O17: =G17*(1+O26) -> 6113.82 | T17: Investment, education & others | U17: 2172 | AE17: =447.489-79.029 -> 368.46 | AF17: =644.537-AE17 -> 276.077 | AG17: =1141.663-SUM(AE17:AF17) -> 497.126 | AH17: =1559.314-SUM(AE17:AG17) -> 417.651 | AI17: =700.646-216.789330046001 -> 483.85667 | AJ17: =690.291-218.914715178998 -> 471.37628 | AK17: =800.72-418.798043028 -> 381.92196 | AL17: =1045.863-284.415366719997 -> 761.44763 | AM17: =1039.158-421.143155609001 -> 618.01484 | AN17: =1047.914-270.783909041 -> 777.13009 | AO17: =1256.65-402.685979647002 -> 853.96402 | AP17: =1723.226-455.357728890998 -> 1267.8683 | AQ17: =1492.142-439.266 -> 1052.876 | AR17: =2281-AQ17 -> 1228.124 | AS17: =3720-AR17-AQ17 -> 1439 | AT17: =5363-AS17-AR17-AQ17 -> 1643 | AU17: 1609 | AV17: =3017-AU17 -> 1408 | AW17: =4477-AV17-AU17 -> 1460 | AX17: =6129-AW17-AV17-AU17 -> 1652 | AY17: 1707 | AZ17: =3198-AY17 -> 1491 | BA17: =4651-AZ17-AY17 -> 1453 | BB17: =6132-AY17-AZ17-BA17 -> 1481 | BC17: 1638 | BD17: =AQ17+AR17 -> 2281 | BE17: =AU17+AV17 -> 3017 | BI17: =AY17+AZ17 -> 3198 | BL17: =BA17+AZ17+AY17 -> 4651 | BN17: =BI17/N17 -> 0.47434699 | BP17: 3131 | BQ17: =BP17-BC17 -> 1493 | CD17: =AE17+AF17 -> 644.537 | CE17: =AI17+AJ17 -> 955.23295 | CF17: =AM17+AN17 -> 1395.1449 | CG17: =AQ17+AR17 -> 2281 | CI17: =CG17/CF17-1 -> 0.63495558
A19: Net revenue growth | B19: Tổng | C19: =C10/B10-1 -> 0.19399988 | D19: =D10/C10-1 -> 0.0762508 | E19: =E10/D10-1 -> 0.19533301 | F19: =F10/E10-1 -> 0.23423742 | G19: =G10/F10-1 -> 0.19560474 | H19: =H10/G10-1 -> 0.19445817 | I19: =I10/H10-1 -> 0.11557677 | J19: =J10/I10-1 -> 0.12595076 | ... L19: =L10/K10-1 -> 0.14965845 | N19: =N10/H10-1 -> 0.055023548 | O19: =O10/G10-1 -> 0.059420921 | AI19: =AI10/AE10-1 -> 0.144145 | AJ19: =AJ10/AF10-1 -> 0.2380665 | AK19: =AK10/AG10-1 -> 0.15517324 | AL19: =AL10/AH10-1 -> 0.23507793 | AM19: =AM10/AI10-1 -> 0.28260395 | AN19: =AN10/AJ10-1 -> 0.16829462 | AO19: =AO10/AK10-1 -> 0.27774662 | AP19: =AP10/AL10-1 -> 0.21845651 | ... BB19: =BB10/AX10-1 -> -0.088028169 | BD19: Net revenue growth | BE19: =BE10/BD10-1 -> 0.2140197 | BI19: =BI10/BE10-1 -> 0.11401595 | BK19: 0.105 | BL19: 0.103
A20: Total IT services | B20: CNTT | C20: =C11/B11-1 -> 0.1777289 | D20: =D11/C11-1 -> 0.064720506 | E20: =E11/D11-1 -> 0.24203085 | F20: =F11/E11-1 -> 0.23431395 | G20: =G11/F11-1 -> 0.22070875 | H20: =H11/G11-1 -> 0.24360075 | I20: =I11/H11-1 -> 0.13717719 | J20: =J11/I11-1 -> 0.14122556 | ... L20: =L11/K11-1 -> 0.16560096 | N20: =N11/H11-1 -> 0.018745334 | O20: =O11/G11-1 -> 0.01593914 | AE20: =AE11/AA11-1 -> #DIV/0! | AF20: =AF11/AB11-1 -> #DIV/0! | AG20: =AG11/AC11-1 -> #DIV/0! | AH20: =AH11/AD11-1 -> #DIV/0! | AI20: =AI11/AE11-1 -> 0.16228498 | AJ20: =AJ11/AF11-1 -> 0.26341309 | AK20: =AK11/AG11-1 -> 0.25191568 | AL20: =AL11/AH11-1 -> 0.27366774 | ... BB20: =BB11/AX11-1 -> 0.21352952 | BD20: Total IT services | BE20: =BE11/BD11-1 -> 0.27284889 | BI20: =BI11/BE11-1 -> 0.11345909 | BK20: 0.106 | BL20: 0.107
A21: Global IT | B21: CNTT nước ngoài | C21: =C12/B12-1 -> 0.28478699 | D21: =D12/C12-1 -> 0.10621223 | E21: =E12/D12-1 -> 0.21170716 | F21: =F12/E12-1 -> 0.3008564 | G21: =G12/F12-1 -> 0.28402673 | H21: =H12/G12-1 -> 0.27441535 | I21: =I12/H12-1 -> 0.14308791 | J21: =J12/I12-1 -> 0.14668042 | ... L21: =L12/K12-1 -> 0.17659111 | N21: =N12/H12-1 -> -3.2307046e-05 | O21: =O12/G12-1 -> 0 | AI21: =AI12/AE12-1 -> 0.096374014 | AJ21: =AJ12/AF12-1 -> 0.20348295 | AK21: =AK12/AG12-1 -> 0.25711212 | AL21: =AL12/AH12-1 -> 0.28081476 | AM21: =AM12/AI12-1 -> 0.29720755 | AN21: =AN12/AJ12-1 -> 0.2838099 | AO21: =AO12/AK12-1 -> 0.30158646 | AP21: =AP12/AL12-1 -> 0.31939752 | ... BB21: =BB12/AX12-1 -> 0.18382619 | BD21: Global IT | BE21: =BE12/BD12-1 -> 0.29803153 | BI21: =BI12/BE12-1 -> 0.14382763 | BK21: 0.126 | BL21: 0.128 | BN21: =27123-22437 -> 4686
A22: Domestic IT | B22: CNTT trong nước | C22: =C13/B13-1 -> -0.0045872392 | D22: =D13/C13-1 -> -0.026479538 | E22: =E13/D13-1 -> 0.317768 | F22: =F13/E13-1 -> 0.081492481 | G22: =G13/F13-1 -> 0.045797183 | H22: =H13/G13-1 -> 0.13908672 | I22: =I13/H13-1 -> 0.11474807 | J22: =J13/I13-1 -> 0.12 | ... L22: =L13/K13-1 -> 0.12 | N22: =N13/H13-1 -> 0.09 | O22: 0.07 | T22: =O12+O13 -> 31950.27 | AI22: =AI13/AE13-1 -> 0.43320702 | AJ22: =AJ13/AF13-1 -> 0.43600126 | AK22: =AK13/AG13-1 -> 0.23922226 | AL22: =AL13/AH13-1 -> 0.26137094 | AM22: =AM13/AI13-1 -> 0.51767493 | AN22: =AN13/AJ13-1 -> -0.17386135 | AO22: =AO13/AK13-1 -> 0.13349921 | AP22: =AP13/AL13-1 -> 0.019577051 | ... BB22: =BB13/AX13-1 -> 0.29919609 | BD22: Domestic IT | BE22: =BE13/BD13-1 -> 0.17781513 | BI22: =BI13/BE13-1 -> -0.012842466 | BK22: 0.02 | BL22: 0.015 | BN22: =24525-19934 -> 4591 | BO22: =BN22/BN21-1 -> -0.020273154
A23: Total telecom | B23: Viễn thông | C23: =C14/B14-1 -> 0.17749105 | D23: =D14/C14-1 -> 0.10268159 | E23: =E14/D14-1 -> 0.10642296 | F23: =F14/E14-1 -> 0.16105676 | G23: =G14/F14-1 -> 0.073073771 | H23: =H14/G14-1 -> 0.11413387 | I23: =I14/H14-1 -> 0.10772288 | J23: =J14/I14-1 -> 0.115 | ... L23: =L14/K14-1 -> 0.12 | N23: =N14/H14-1 -> 0.12 | O23: =O14/G14-1 -> 0.11859547 | V23: =#REF!/F14-1 -> #REF! | W23: =O14/#REF!-1 -> #REF! | AI23: =AI14/AE14-1 -> 0.096363595 | AJ23: =AJ14/AF14-1 -> 0.15531752 | AK23: =AK14/AG14-1 -> 0.081231122 | AL23: =AL14/AH14-1 -> 0.094926504 | AM23: =AM14/AI14-1 -> 0.1866614 | AN23: =AN14/AJ14-1 -> 0.12637371 | AO23: =AO14/AK14-1 -> 0.20120952 | AP23: =AP14/AL14-1 -> 0.13541602 | ... BB23: =BB14/AX14-1 -> 0.085239085 | BD23: Total telecom | BE23: =BE14/BD14-1 -> 0.073158032 | BI23: =BI14/BE14-1 -> 0.13500728 | BK23: 0.123 | BL23: 0.116
A24: Telecom | B24: Viễn thông | C24: =C15/B15-1 -> 0.18043166 | D24: =D15/C15-1 -> 0.11006597 | E24: =E15/D15-1 -> 0.11150038 | F24: =F15/E15-1 -> 0.15527709 | G24: =G15/F15-1 -> 0.088272938 | H24: =H15/G15-1 -> 0.11326222 | I24: =I15/H15-1 -> 0.10623447 | J24: =J15/I15-1 -> 0.11802615 | ... L24: =L15/K15-1 -> 0.11541306 | N24: =N15/H15-1 -> 0.13479475 | O24: =O15/G15-1 -> 0.11935467 | AI24: =AI15/AE15-1 -> 0.092968651 | AJ24: =AJ15/AF15-1 -> 0.14757855 | AK24: =AK15/AG15-1 -> 0.089645558 | AL24: =AL15/AH15-1 -> 0.11544494 | AM24: =AM15/AI15-1 -> 0.18422126 | AN24: =AN15/AJ15-1 -> 0.11919644 | AO24: =AO15/AK15-1 -> 0.18215146 | AP24: =AP15/AL15-1 -> 0.13952995 | ... BB24: =BB15/AX15-1 -> 0.082424771 | BD24: Telecom | BE24: =BE15/BD15-1 -> 0.073151017 | BI24: =BI15/BE15-1 -> 0.13356766 | BL24: 0.115
A25: Digital content | B25: Quảng cáo online | C25: =C16/B16-1 -> 0.13214872 | D25: =D16/C16-1 -> -0.016036695 | E25: =E16/D16-1 -> 0.014331946 | F25: =F16/E16-1 -> 0.27592647 | G25: =G16/F16-1 -> -0.20044259 | H25: =H16/G16-1 -> 0.13709677 | I25: =I16/H16-1 -> 0.14184397 | J25: 0.14 | K25: 0.14 | L25: 0.14 | N25: 0.14 | O25: =Assumptions!AG20 -> 0.1 | AI25: =AI16/AE16-1 -> 0.18102367 | AJ25: =AJ16/AF16-1 -> 0.32861099 | AK25: =AK16/AG16-1 -> -0.08029813 | AL25: =AL16/AH16-1 -> -0.15930601 | AM25: =AM16/AI16-1 -> 0.2429745 | AN25: =AN16/AJ16-1 -> 0.2651907 | AO25: =AO16/AK16-1 -> 0.63466361 | AP25: =AP16/AL16-1 -> 0.06778369 | ... BB25: =BB16/AX16-1 -> 0.13777778 | BD25: Digital content | BE25: =BE16/BD16-1 -> 0.073359073 | BI25: =BI16/BE16-1 -> 0.17625899 | BL25: 0.144
A26: Education & Investments | B26: Giáo dục | C26: =C17/B17-1 -> 0.56490823 | D26: =D17/C17-1 -> 0.015765867 | E26: =E17/D17-1 -> 0.34584942 | F26: =F17/E17-1 -> 0.67586601 | G26: =G17/F17-1 -> 0.52488927 | H26: =H17/G17-1 -> 0.14283051 | I26: =I17/H17-1 -> 0.00048947626 | J26: =J17/I17-1 -> 0.05 | ... L26: =L17/K17-1 -> 0.12 | N26: =N17/H17-1 -> 0.1 | O26: 0.14 | AI26: =AI17/AE17-1 -> 0.31318642 | AJ26: =AJ17/AF17-1 -> 0.70740875 | AK26: =AK17/AG17-1 -> -0.23174013 | AL26: =AL17/AH17-1 -> 0.82316727 | AM26: =AM17/AI17-1 -> 0.27726842 | AN26: =AN17/AJ17-1 -> 0.64864062 | AO26: =AO17/AK17-1 -> 1.2359647 | AP26: =AP17/AL17-1 -> 0.66507612 | ... BB26: =BB17/AX17-1 -> -0.1035109 | BD26: Investment, education & others | BE26: =BE17/BD17-1 -> 0.3226655 | BI26: =BI17/BE17-1 -> 0.059993371 | BK26: 0.044 | BL26: 0.039
A28: % net revenue contribution
A29: Total IT services | B29: =B11/B$3 -> 0.5773172 | C29: =C11/C$3 -> 0.56944993 | D29: =D11/D$3 -> 0.56334919 | E29: =E11/E$3 -> 0.58535744 | F29: =F11/F$3 -> 0.58539374 | G29: =G11/G$3 -> 0.59768633 | H29: =H11/H$3 -> 0.62228724 | I29: =I11/I$3 -> 0.63347761 | ... L29: =L11/L$3 -> 0.65941001 | N29: =N11/N$3 -> 0.6008776 | O29: =O11/O$3 -> 0.57315443 | AI29: =AI11/AI$10 -> 0.55064205 | AJ29: =AJ11/AJ$10 -> 0.5750388 | AK29: =AK11/AK$10 -> 0.60028066 | AL29: =AL11/AL$10 -> 0.60612764 | AM29: =AM11/AM$10 -> 0.57974973 | AN29: =AN11/AN$10 -> 0.56590313 | AO29: =AO11/AO$10 -> 0.58877573 | AP29: =AP11/AP$10 -> 0.6020481 | ... BB29: =BB11/BB$10 -> 0.84232158 | BD29: =BD11/BD$10 -> 0.58768518 | BE29: =BE11/BE$10 -> 0.61616334 | BI29: =BI11/BI$10 -> 0.61585534
A30: Global IT | B30: =B12/B$3 -> 0.36373053 | C30: =C12/C$3 -> 0.39138718 | D30: =D12/D$3 -> 0.4022829 | E30: =E12/E$3 -> 0.40779353 | F30: =F12/F$3 -> 0.42980452 | G30: =G12/G$3 -> 0.46159196 | H30: =H12/H$3 -> 0.49249954 | I30: =I12/I$3 -> 0.50396189 | ... L30: =L12/L$3 -> 0.53636079 | N30: =N12/N$3 -> 0.46678972 | O30: =O12/O$3 -> 0.43570132 | AI30: =AI12/AI$10 -> 0.41777763 | AJ30: =AJ12/AJ$10 -> 0.40657961 | AK30: =AK12/AK$10 -> 0.4276859 | AL30: =AL12/AL$10 -> 0.38548268 | AM30: =AM12/AM$10 -> 0.4225344 | AN30: =AN12/AN$10 -> 0.44678023 | AO30: =AO12/AO$10 -> 0.43566554 | AP30: =AP12/AP$10 -> 0.41741735 | ... BB30: =BB12/BB$10 -> 0.6107859 | BD30: =BD12/BD$10 -> 0.46457833 | BE30: =BE12/BE$10 -> 0.49672779 | BI30: =BI12/BI$10 -> 0.5100205
A31: Domestic IT | B31: =B13/B$3 -> 0.21358667 | C31: =C13/C$3 -> 0.17806274 | D31: =D13/D$3 -> 0.16106629 | E31: =E13/E$3 -> 0.17756391 | F31: =F13/F$3 -> 0.15558922 | G31: =G13/G$3 -> 0.13609437 | H31: =H13/H$3 -> 0.1297877 | I31: =I13/I$3 -> 0.12951573 | ... L31: =L13/L$3 -> 0.12304923 | N31: =N13/N$3 -> 0.13408788 | O31: =O13/O$3 -> 0.13745311 | AI31: =AI13/AI$10 -> 0.13286442 | AJ31: =AJ13/AJ$10 -> 0.16845919 | AK31: =AK13/AK$10 -> 0.17259476 | AL31: =AL13/AL$10 -> 0.22064497 | AM31: =AM13/AM$10 -> 0.15721532 | AN31: =AN13/AN$10 -> 0.1191229 | AO31: =AO13/AO$10 -> 0.15311019 | AP31: =AP13/AP$10 -> 0.18463075 | ... BB31: =BB13/BB$10 -> 0.23147341 | BD31: =BD13/BD$10 -> 0.12310684 | BE31: =BE13/BE$10 -> 0.11943554 | BI31: =BI13/BI$10 -> 0.10583484
A32: Total telecom | B32: =B14/B$3 -> 0.38042471 | C32: =C14/C$3 -> 0.37516477 | D32: =D14/D$3 -> 0.38437814 | E32: =E14/E$3 -> 0.35578772 | F32: =F14/F$3 -> 0.33469228 | G32: =G14/G$3 -> 0.30039207 | H32: =H14/H$3 -> 0.28019633 | I32: =I14/I$3 -> 0.27784706 | ... L32: =L14/L$3 -> 0.26279617 | N32: =N14/N$3 -> 0.29744724 | O32: =O14/O$3 -> 0.31717004 | AI32: =AI14/AI$10 -> 0.38557786 | AJ32: =AJ14/AJ$10 -> 0.37041454 | AK32: =AK14/AK$10 -> 0.35594691 | AL32: =AL14/AL$10 -> 0.32273599 | AM32: =AM14/AM$10 -> 0.3567355 | AN32: =AN14/AN$10 -> 0.35712327 | AO32: =AO14/AO$10 -> 0.33462567 | AP32: =AP14/AP$10 -> 0.30074082 | ... BB32: =BB14/BB$10 -> 0.32507162 | BD32: =BD14/BD$10 -> 0.31788463 | BE32: =BE14/BE$10 -> 0.28100075 | BI32: =BI14/BI$10 -> 0.28629563
A33: Telecom | B33: =B15/B$3 -> 0.35725543 | C33: =C15/C$3 -> 0.35319569 | D33: =D15/D$3 -> 0.3642929 | E33: =E15/E$3 -> 0.33874384 | F33: =F15/F$3 -> 0.31707271 | G33: =G15/G$3 -> 0.288609 | H33: =H15/H$3 -> 0.26899484 | I33: =I15/I$3 -> 0.26638108 | ... L33: =L15/L$3 -> 0.25092637 | N33: =N15/N$3 -> 0.28932819 | O33: =O15/O$3 -> 0.30493567 | AI33: =AI15/AI$10 -> 0.36956405 | AJ33: =AJ15/AJ$10 -> 0.35220448 | AK33: =AK15/AK$10 -> 0.3409558 | AL33: =AL15/AL$10 -> 0.30423029 | AM33: =AM15/AM$10 -> 0.34121648 | AN33: =AN15/AN$10 -> 0.3374029 | AO33: =AO15/AO$10 -> 0.31544705 | AP33: =AP15/AP$10 -> 0.28452352 | ... BB33: =BB15/BB$10 -> 0.30912941 | BD33: =BD15/BD$10 -> 0.30716709 | BE33: =BE15/BE$10 -> 0.27152498 | BI33: =BI15/BI$10 -> 0.27629043
A34: Digital content | B34: =B16/B$3 -> 0.023169283 | C34: =C16/C$3 -> 0.021969076 | D34: =D16/D$3 -> 0.020085248 | E34: =E16/E$3 -> 0.017043877 | F34: =F16/F$3 -> 0.017619571 | G34: =G16/G$3 -> 0.011783062 | H34: =H16/H$3 -> 0.0112174 | I34: =I16/I$3 -> 0.01146598 | ... L34: =L16/L$3 -> 0.011487567 | N34: =N16/N$3 -> 0.012120667 | O34: =O16/O$3 -> 0.012234367 | AI34: =AI16/AI$10 -> 0.016013809 | AJ34: =AJ16/AJ$10 -> 0.018210059 | AK34: =AK16/AK$10 -> 0.014991109 | AL34: =AL16/AL$10 -> 0.018505696 | AM34: =AM16/AM$10 -> 0.01551902 | AN34: =AN16/AN$10 -> 0.019720366 | AO34: =AO16/AO$10 -> 0.019178622 | AP34: =AP16/AP$10 -> 0.016217305 | ... BB34: =BB16/BB$10 -> 0.015942209 | BD34: =BD16/BD$10 -> 0.010717537 | BE34: =BE16/BE$10 -> 0.0094757652 | BI34: =BI16/BI$10 -> 0.010005201
A35: Investment, education & others | B35: =B17/B$3 -> 0.042258096 | C35: =C17/C$3 -> 0.0553853 | D35: =D17/D$3 -> 0.052272665 | E35: =E17/E$3 -> 0.058854842 | F35: =F17/F$3 -> 0.079913984 | G35: =G17/G$3 -> 0.10192349 | H35: =H17/H$3 -> 0.097519777 | I35: =I17/I$3 -> 0.08734086 | ... L35: =L17/L$3 -> 0.077793823 | N35: =N17/N$3 -> 0.10167516 | O35: =O17/O$3 -> 0.10967554 | AI35: =AI17/AI$10 -> 0.063780091 | AJ35: =AJ17/AJ$10 -> 0.054546662 | AK35: =AK17/AK$10 -> 0.043772428 | AL35: =AL17/AL$10 -> 0.071136367 | AM35: =AM17/AM$10 -> 0.063514771 | AN35: =AN17/AN$10 -> 0.0769736 | AO35: =AO17/AO$10 -> 0.076598601 | AP35: =AP17/AP$10 -> 0.097211074 | ... BB35: =BB17/BB$10 -> 0.092228173 | BD35: =BD17/BD$10 -> 0.094388811 | BE35: =BE17/BE$10 -> 0.10283591 | BI35: =BI17/BI$10 -> 0.097849035
A37: Production costs by factors | B37: =SUM(B38:B39,B53:B55) -> 20176.807 | C37: =SUM(C38:C39,C53:C55) -> 23714.657 | D37: =SUM(D38:D39,D53:D55) -> 25248.395 | E37: =SUM(E38:E39,E53:E55) -> 30325.982 | F37: =SUM(F38:F39,F53:F55) -> 37206.167 | G37: =SUM(G38:G39,G53:G55) -> 44119.808 | H37: =SUM(H38:H39,H53:H55) -> 52322.78 | I37: =SUM(I38:I39,I53:I55) -> 62507.503
A38: Raw materials | B38: 3565.6454 | C38: 4163.1202 | D38: 3526.4899 | E38: 5172.5485 | F38: 5295.4224 | G38: =Data!AX300 -> 5506.3275 | H38: =Data!AY300 -> 6642.59 | I38: =Data!AZ300 -> 8013.3269
A39: Labour costs | B39: 7707.9083 | C39: 10267.171 | D39: 12390.314 | E39: 15080.424 | F39: 18798.003 | G39: =Data!AX301 -> 22824.862 | H39: =Data!AY301 -> 26455.12 | I39: =Data!AZ301 -> 30662.765 | J39: =J40*J45 -> 30690 | K39: =K40*K45 -> 37510 | L39: =L40*L45 -> 44561.88 | N39: =N40*N45 -> 33542 | O39: =O40*O45 -> 25781.165 | T39: [3.COGs Assumption]
A40: # employees | B40: =16940+9531+1372 -> 27843 | C40: =17628+9361+1792 -> 28781 | D40: =18728+9803+2120 -> 30651 | E40: =24068+10346+2766 -> 37180 | F40: =28533+9478+4397 -> 42408 | G40: 48162 | I40: 54100 | J40: 45000 | K40: 50000 | L40: 55000 | N40: 54100 | O40: =Assumptions!AG30 -> 50000
A41: % growth | C41: =C40/B40-1 -> 0.033688898 | D41: =D40/C40-1 -> 0.06497342 | E41: =E40/D40-1 -> 0.21301099 | F41: =F40/E40-1 -> 0.14061323 | G41: =G40/F40-1 -> 0.13568195 | I41: =I40/C40-1 -> 0.87971231 | J41: =J40/N40-1 -> -0.16820702 | K41: =K40/J40-1 -> 0.11111111 | L41: =L40/K40-1 -> 0.1 | N41: =N40/H40-1 -> #DIV/0! | O41: =O40/G40-1 -> 0.038162867
A42: technology | B42: 16940 | C42: 17628 | D42: 18728 | E42: 24068 | F42: 28533
A43: telecommunications | B43: 9531 | C43: 9355 | D43: 9803 | E43: 10346 | F43: 9478
...

Sheet Valuation
B3: DISCOUNTED FCFF MODEL | J3: 2026 | R3: 2023
B5: Assumption | F5: Present Value | N5: Present Value
B6: Net sales growth rate in long-term | F6: Present value of first stage (2025-2028 FCFF) | J6: =D36 -> 29669.934 | N6: Present value of next 4-year cash flow | R6: =P36 -> #REF!
B7: terminal g | C7: 0.025 | F7: WACC | J7: =C27 -> 0.099249688 | N7: WACC | R7: =C27 -> 0.099249688
F8: Growth rate to perpeptuity | J8: =C7 -> 0.025 | N8: Growth rate to perpeptuity | R8: =C6 -> 0
F9: Terminal value (2028 onwards) | J9: =G36 -> 135886.66 | N9: Terminal value | R9: =S36 -> 116282.71
B10: WACC | F10: Terminal value/ Total company value | J10: =J9/(J9+J6) -> 0.82078676 | N10: Terminal value/ Total company value | R10: =R9/(R9+R6) -> #REF!
